Workbook

Sheet README CARA PAKAI
A1: ARTABOGA GATSU - WORKFLOW (BOBOT PEK = MASTER JADWAL)
A3: 1. ALUR DATA (siapa menentukan apa)
A4: RAB UPDATE = daftar pekerjaan + bobot + nilai (APA pekerjaannya). BOBOT PEK = salinan RAB sekaligus MASTER JADWAL (KAPAN dikerjakan). TS = referensi Time Schedule + kalender. RENCANA MINGGUAN = tampilan mingguan otomatis. CETAK RENCANA MINGGUAN = layout cetak. PDF = output final. Alur: RAB -> BOBOT PEK (jadwal) -> RENCANA MINGGUAN (filter minggu aktif) -> CETAK -> PDF.
A5: 2. MENGATUR JADWAL PEKERJAAN (SATU TEMPAT: BOBOT PEK)
A6: Buka sheet BOBOT PEK, geser ke kanan ke blok 'MASTER JADWAL PEKERJAAN' (kolom U ke kanan). Di baris subtotal tiap seksi, ubah START WEEK dan FINISH WEEK (sel kuning, dropdown 1-16). Jangan mengubah jadwal di sheet lain. DURASI, START DATE, FINISH DATE, GANTT (blok hitam di W1..W16), PROGRESS, STATUS = otomatis.
A7: 3. JADWAL AWAL (auto-fill dari TS)
A8: Saat pertama dibuat, START WEEK / FINISH WEEK diisi otomatis mengikuti jadwal yang sudah ada di TS/Time Schedule. User tinggal menyesuaikan bila kondisi lapangan berbeda (override manual).
A9: 4. PILIH MINGGU + CETAK
A10: Di sheet 'CETAK RENCANA MINGGUAN' pilih minggu pada kotak kuning B10. Tabel otomatis menampilkan hanya item yang aktif minggu itu (START WEEK <= minggu <= FINISH WEEK). Ctrl+P untuk cetak; PDF: scripts/generate_pdf.py (simpan file dulu, Ctrl+S).
A11: 5. MENGEDIT DATA PERENCANAAN (RENCANA MINGGUAN)
A12: Kolom D (uraian/sub item), K (volume), L (satuan), M (lokasi), N (PIC), P (catatan) = input manual (sel kuning). Kolom A (minggu) sebaiknya sesuai jadwal BOBOT PEK - baris di luar jadwal ditandai MERAH otomatis. Kolom E-J, O, Q = formula, jangan ditimpa.
A13: 6. TAMBAH / SISIP BARIS
... A22: - Angka tidak berubah: tekan F9. - Muncul '####': tarik tepi kolom. - Baris RENCANA merah: minggu baris itu di luar jadwal BOBOT PEK - ubah START/FINISH WEEK di BOBOT PEK atau pindahkan baris ke minggu yang sesuai. - Perlu minggu baru: tambahkan pilihan 'Minggu Ke-N' di Data Validation B10 CETAK.

Sheet RAB UPDATE
B1: PT Artaboga Cemerlang | G1: QUOTATION
B2: Kawasan Industri Candi Jl. Gatot Subroto No.1 | G2: Q-0009VI26 Rev4
B3: Purwoyoso, Kec. Ngaliyan, Kota Semarang | G3: Tanggal | H3: : 13 JULI 2026
B4: Pekerjaan Gudang Umum
B6: No | C6: Uraian Pekerjaan | D6: Spesifikasi | E6: Volume | F6: Sat. | G6: Harga satuan | H6: Jumlah harga | I6: Grand total | J6: Bobot pekerjaan
B8: A | C8: Pekerjaan Persiapan | K8: A | L8: Pekerjaan Persiapan
B9: 1 | C9: Pekerjaan Persiapan | D9: Termasuk Pembuatan Gudang | E9: 1 | F9: Is | G9: 20000000 | H9: =E9*G9 -> 20000000 | I9: 3908731694 | J9: =H9/I9*100 -> 0.51167493 | K9: 1 | L9: Pekerjaan Persiapan | O9: 1,00 | P9: 1300000 | Q9: 1300000
B10: 2 | C10: Pembersihan Lahan | E10: 1 | F10: Is | G10: 10000000 | H10: =E10*G10 -> 10000000 | I10: 3908731694 | J10: =H10/I10*100 -> 0.25583746 | K10: 2 | L10: Pembersihan Lahan | O10: 1,00 | P10: 5000000 | Q10: 5000000
B11: 3 | C11: Direksi Kit+Gudang Sementara | H11: =E11*G11 -> 0 | I11: 3908731694 | J11: =H11/I11*100 -> 0 | K11: 3 | L11: Skafolding dan Alat Bantu Pekerjaan | O11: 1,00 | P11: 2000000 | Q11: 2000000
B12: 4 | C12: Administrasi Lapangan | E12: 1 | F12: Is | G12: 5000000 | H12: =E12*G12 -> 5000000 | I12: 3908731694 | J12: =H12/I12*100 -> 0.12791873 | K12: 4 | L12: Biaya gambar | O12: 1,00 | P12: 1100000 | Q12: 1100000
B13: 5 | C13: Skafolding dan Alat Bantu Pekerjaan | D13: Sewa Skafolding 40 set Selama 2 bulan | E13: 1 | F13: Is | G13: 15000000 | H13: =E13*G13 -> 15000000 | I13: 3908731694 | J13: =H13/I13*100 -> 0.38375619
H14: =SUM(H8:H13) -> 50000000 | I14: 3908731694 | J14: =H14/I14*100 -> 1.2791873 | K14: B | L14: Pekerjaan Struktur - pondasi
B15: B | C15: Pekerjaan Area Gudang Umum+Gudang SPM Uk.46x54 M
B16: 1 | C16: Pekerjaan Bak Kontrol | D16: Rangka siku 40x40x3mm + besi beton | E16: 4 | F16: unit | G16: 650000 | H16: =E16*G16 -> 2600000 | I16: 3908731694 | J16: =H16/I16*100 -> 0.06651774
B17: 2 | C17: Pasang aluminium bubble dibawah atap+plat strip | D17: Aluminium bubble tebal 10 mm + plat strip 2mm x 3cm | E17: 2875 | F17: m² | G17: 120000 | H17: =E17*G17 -> 345000000 | I17: 3908731694 | J17: =H17/I17*100 -> 8.8263925
B18: 3 | C18: Pekerjaan finishing cat sisi luar samping dan belakang | D18: Cat dinding exterior ex. Dulux Catylac setara | E18: 1230 | F18: m² | G18: 57500 | H18: =E18*G18 -> 70725000 | I18: 3908731694 | J18: =H18/I18*100 -> 1.8094105
B19: 4 | C19: Pasang turbin ventilator 32" | D19: Turbin Ventilator 32 " | E19: 18 | F19: unit | G19: 2500000 | H19: =E19*G19 -> 45000000 | I19: 3908731694 | J19: =H19/I19*100 -> 1.1512686
B20: 5 | C20: Bongkar atap existing | D20: diganti bening | E20: 196 | F20: m² | G20: 25000 | H20: =E20*G20 -> 4900000 | I20: 3908731694 | J20: =H20/I20*100 -> 0.12536036
B21: 6 | C21: Pasang atap fiber bening | D21: Fiber bening ex. Clandianplast Setara | E21: 196 | F21: m² | G21: 143000 | H21: =E21*G21 -> 28028000 | I21: 3908731694 | J21: =H21/I21*100 -> 0.71706124
B22: 7 | C22: pekerjaan refinishing kanopi loading dock | D22: Cat Ftalit Royal Blue | E22: 290 | F22: m² | G22: 85000 | H22: =E22*G22 -> 24650000 | I22: 3908731694 | J22: =H22/I22*100 -> 0.63063935
B23: 8 | C23: Perbaikan loading dock | D23: Penambahan besi siku 70 x 70 mm | E23: 45 | F23: m | G23: 344500 | H23: =E23*G23 -> 15502500 | I23: 3908731694 | J23: =H23/I23*100 -> 0.39661203
B24: 9 | C24: Perbaikan dinding dan cat dinding loading dock | D24: Cat dinding exterior ex. Dulux Catylac setara | E24: 37 | F24: m | G24: 57500 | H24: =E24*G24 -> 2127500 | I24: 3908731694 | J24: =H24/I24*100 -> 0.05442942
B25: 10 | C25: Servis kebocoran pipa talang | E25: 1 | F25: ls | G25: 5200000 | H25: =E25*G25 -> 5200000 | I25: 3908731694 | J25: =H25/I25*100 -> 0.13303548
B26: 11 | C26: Cor ulang lantai gudang utama sisi pintu dalam (4mx5m) | D26: inc kupas, pembesian M8, cor | E26: 60 | F26: m² | G26: 1100000 | H26: =E26*G26 -> 66000000 | I26: 3908731694 | J26: =H26/I26*100 -> 1.6885273
B27: 12 | C27: Pembongkaran pintu rolling door | D27: inc buang | E27: 1 | F27: ls | G27: 2500000 | H27: =E27*G27 -> 2500000 | I27: 3908731694 | J27: =H27/I27*100 -> 0.063959366
B28: 13 | C28: Perapian kabel dalam gudang | D28: cable tray custom | E28: 54 | F28: m | G28: 360000 | H28: =E28*G28 -> 19440000 | I28: 3908731694 | J28: =H28/I28*100 -> 0.49734803
H29: =SUM(H16:H28) -> 631673000 | I29: 3908731694 | J29: =H29/I29*100 -> 16.160562
H30: =E30*G30 -> 0
B31: C | C31: PEKERJAAN AREA GUDANG PARKIR SISI SAMPING UK.4,75X37M | H31: =E31*G31 -> 0
B32: 1 | C32: Perbaikan atap existing | E32: 30 | F32: m² | G32: 40000 | H32: =E32*G32 -> 1200000 | I32: 3908731694 | J32: =H32/I32*100 -> 0.030700496
B33: 2 | C33: Pekerjaan bongkaran lantai paving block existing | D33: Termasuk pembuangan bekas bongkaran | E33: 105 | F33: m² | G33: 35000 | H33: =E33*G33 -> 3675000 | I33: 3908731694 | J33: =H33/I33*100 -> 0.094020268
B34: 3 | C34: Pekerjaan pasang rangka kolom dan atap area parkir + penutup + talang | D34: Rangka menggunakan besi CNP 100 double+talang+cat ftalit royal blue+atap zincalum 0,3 mm ex. Kencana | E34: 40 | F34: m² | G34: 275000 | H34: =E34*G34 -> 11000000 | I34: 3908731694 | J34: =H34/I34*100 -> 0.28142121
B35: 4 | C35: Pemasangan atap transparan di area tambahan | D35: polycarbonate transparan | E35: 14 | F35: m² | G35: 160000 | H35: =E35*G35 -> 2240000 | I35: 3908731694 | J35: =H35/I35*100 -> 0.057307592
B36: 5 | C36: Pemadatan dan peninggian lantai parkir | D36: Peninggian dengan pasir 10cm + pemadatan | E36: 185 | F36: m² | G36: 150000 | H36: =E36*G36 -> 27750000 | I36: 3908731694 | J36: =H36/I36*100 -> 0.70994896
B37: 6 | C37: Pasang paving block lantai parkir | D37: Paving blok K-150 tebal 6 cm | E37: 93 | F37: m² | G37: 185000 | H37: =E37*G37 -> 17205000 | I37: 3908731694 | J37: =H37/I37*100 -> 0.44016836
B38: 7 | C38: Instalasi penerangan + downlight exposed + bohlam 12 w | D38: Kabel ex. Eterna+rumah lampu | E38: 10 | F38: unit | G38: 364000 | H38: =E38*G38 -> 3640000 | I38: 3908731694 | J38: =H38/I38*100 -> 0.093124837
B39: 8 | C39: Perapian kabel existing dan dinding existing | D39: Pasang kabel tray + perapian dinding | E39: 1 | F39: Is | G39: 4500000 | H39: =E39*G39 -> 4500000 | I39: 3908731694 | J39: =H39/I39*100 -> 0.11512686
B40: 9 | C40: Pembuatan saluran bawah paving | D40: sudetan 4" | E40: 6 | F40: Is | G40: 600000 | H40: =E40*G40 -> 3600000 | I40: 3908731694 | J40: =H40/I40*100 -> 0.092101487
B41: 10 | C41: Pembongkaran besi kerangkeng motor | D41: inc buang | E41: 1 | F41: Is | G41: 1000000 | H41: =E41*G41 -> 1000000 | I41: 3908731694 | J41: =H41/I41*100 -> 0.025583746
H42: =SUM(H32:H41) -> 75810000 | I42: 3908731694 | J42: =H42/I42*100 -> 1.9395038
...

Sheet BOBOT PEK
B1: PT Artaboga Cemerlang | G1: QUOTATION
B2: Kawasan Industri Candi Jl. Gatot Subroto No.1 | G2: Q-0009VI26 Rev4
B3: Purwoyoso, Kec. Ngaliyan, Kota Semarang | G3: Tanggal | H3: : 13 JULI 2026
B4: Pekerjaan Gudang Umum
U5: MASTER JADWAL PEKERJAAN (single source of truth) - setiap baris ITEM PEKERJAAN punya START WEEK / FINISH WEEK sendiri (sel kuning kolom U/V). Baris SUBTOTAL section (angka MIN/MAX) dihitung otomatis dari item-nya. DURASI, tanggal, Gantt, progress mengikuti otomatis.
B6: No | C6: Uraian Pekerjaan | D6: Spesifikasi | E6: Volume | F6: Sat. | G6: Harga satuan | H6: Jumlah harga | I6: Grand total | J6: Bobot pekerjaan | U6: START WEEK | V6: FINISH WEEK | W6: DURASI (MGG) | X6: START DATE | Y6: FINISH DATE | Z6: PROGRESS % | AA6: STATUS | AB6: W1 | AC6: W2 | AD6: W3 | AE6: W4 | AF6: W5 | AG6: W6 | AH6: W7 | AI6: W8 | AJ6: W9 | AK6: W10 | AL6: W11 | AM6: W12 | AN6: W13 | AO6: W14 | AP6: W15 | AQ6: W16 | AR6: ID Pekerjaan
U7: Keterangan : setiap baris item = START WEEK/FINISH WEEK sendiri (kuning, pilihan 1-16). Baris subtotal section = MIN/MAX otomatis dari seluruh item section tsb. DURASI, START/FINISH DATE, GANTT mengikuti otomatis di baris masing-masing. PROGRESS/STATUS hanya tersedia di baris subtotal (sumber data mingguan per section, bukan per item).
B8: A | C8: PEKERJAAN PERSIAPAN | K8: A | L8: Pekerjaan Persiapan
B9: 1 | C9: Pekerjaan Persiapan | D9: Termasuk Pembuatan Gudang | E9: 1 | F9: Is | G9: 20000000 | H9: =E9*G9 -> 20000000 | I9: 3908731694 | J9: =H9/I9*100 -> 0.51167493 | K9: 1 | L9: Pekerjaan Persiapan | O9: 1,00 | P9: 1300000 | Q9: 1300000 | U9: 1 | V9: 4 | W9: =MAX(1,V9-U9+1) -> 4 | X9: {=INDEX('KALENDER MINGGU'!$B$6:$B$21,U9)} -> 46226 | Y9: {=INDEX('KALENDER MINGGU'!$C$6:$C$21,V9)} -> 46253 | AB9: =IF(AND($U9<=1,$V9>=1),"■","") -> ■ | AC9: =IF(AND($U9<=2,$V9>=2),"■","") -> ■ | AD9: =IF(AND($U9<=3,$V9>=3),"■","") -> ■ | AE9: =IF(AND($U9<=4,$V9>=4),"■","") -> ■ | AF9: =IF(AND($U9<=5,$V9>=5),"■","") | AG9: =IF(AND($U9<=6,$V9>=6),"■","") | AH9: =IF(AND($U9<=7,$V9>=7),"■","") | AI9: =IF(AND($U9<=8,$V9>=8),"■","") | AJ9: =IF(AND($U9<=9,$V9>=9),"■","") | AK9: =IF(AND($U9<=10,$V9>=10),"■","") | AL9: =IF(AND($U9<=11,$V9>=11),"■","") | AM9: =IF(AND($U9<=12,$V9>=12),"■","") | AN9: =IF(AND($U9<=13,$V9>=13),"■","") | AO9: =IF(AND($U9<=14,$V9>=14),"■","") | AP9: =IF(AND($U9<=15,$V9>=15),"■","") | AQ9: =IF(AND($U9<=16,$V9>=16),"■","") | AR9: A-1
B10: 2 | C10: Pembersihan Lahan | E10: 1 | F10: Is | G10: 10000000 | H10: =E10*G10 -> 10000000 | I10: 3908731694 | J10: =H10/I10*100 -> 0.25583746 | K10: 2 | L10: Pembersihan Lahan | O10: 1,00 | P10: 5000000 | Q10: 5000000 | U10: 1 | V10: 4 | W10: =MAX(1,V10-U10+1) -> 4 | X10: {=INDEX('KALENDER MINGGU'!$B$6:$B$21,U10)} -> 46226 | Y10: {=INDEX('KALENDER MINGGU'!$C$6:$C$21,V10)} -> 46253 | AB10: =IF(AND($U10<=1,$V10>=1),"■","") -> ■ | AC10: =IF(AND($U10<=2,$V10>=2),"■","") -> ■ | AD10: =IF(AND($U10<=3,$V10>=3),"■","") -> ■ | AE10: =IF(AND($U10<=4,$V10>=4),"■","") -> ■ | AF10: =IF(AND($U10<=5,$V10>=5),"■","") | AG10: =IF(AND($U10<=6,$V10>=6),"■","") | AH10: =IF(AND($U10<=7,$V10>=7),"■","") | AI10: =IF(AND($U10<=8,$V10>=8),"■","") | AJ10: =IF(AND($U10<=9,$V10>=9),"■","") | AK10: =IF(AND($U10<=10,$V10>=10),"■","") | AL10: =IF(AND($U10<=11,$V10>=11),"■","") | AM10: =IF(AND($U10<=12,$V10>=12),"■","") | AN10: =IF(AND($U10<=13,$V10>=13),"■","") | AO10: =IF(AND($U10<=14,$V10>=14),"■","") | AP10: =IF(AND($U10<=15,$V10>=15),"■","") | AQ10: =IF(AND($U10<=16,$V10>=16),"■","") | AR10: A-2
B11: 3 | C11: Direksi Kit+Gudang Sementara | H11: =E11*G11 -> 0 | I11: 3908731694 | J11: =H11/I11*100 -> 0 | K11: 3 | L11: Skafolding dan Alat Bantu Pekerjaan | O11: 1,00 | P11: 2000000 | Q11: 2000000 | U11: 1 | V11: 4 | W11: =MAX(1,V11-U11+1) -> 4 | X11: {=INDEX('KALENDER MINGGU'!$B$6:$B$21,U11)} -> 46226 | Y11: {=INDEX('KALENDER MINGGU'!$C$6:$C$21,V11)} -> 46253 | AB11: =IF(AND($U11<=1,$V11>=1),"■","") -> ■ | AC11: =IF(AND($U11<=2,$V11>=2),"■","") -> ■ | AD11: =IF(AND($U11<=3,$V11>=3),"■","") -> ■ | AE11: =IF(AND($U11<=4,$V11>=4),"■","") -> ■ | AF11: =IF(AND($U11<=5,$V11>=5),"■","") | AG11: =IF(AND($U11<=6,$V11>=6),"■","") | AH11: =IF(AND($U11<=7,$V11>=7),"■","") | AI11: =IF(AND($U11<=8,$V11>=8),"■","") | AJ11: =IF(AND($U11<=9,$V11>=9),"■","") | AK11: =IF(AND($U11<=10,$V11>=10),"■","") | AL11: =IF(AND($U11<=11,$V11>=11),"■","") | AM11: =IF(AND($U11<=12,$V11>=12),"■","") | AN11: =IF(AND($U11<=13,$V11>=13),"■","") | AO11: =IF(AND($U11<=14,$V11>=14),"■","") | AP11: =IF(AND($U11<=15,$V11>=15),"■","") | AQ11: =IF(AND($U11<=16,$V11>=16),"■","") | AR11: A-3
B12: 4 | C12: Administrasi Lapangan | E12: 1 | F12: Is | G12: 5000000 | H12: =E12*G12 -> 5000000 | I12: 3908731694 | J12: =H12/I12*100 -> 0.12791873 | K12: 4 | L12: Biaya gambar | O12: 1,00 | P12: 1100000 | Q12: 1100000 | U12: 1 | V12: 4 | W12: =MAX(1,V12-U12+1) -> 4 | X12: {=INDEX('KALENDER MINGGU'!$B$6:$B$21,U12)} -> 46226 | Y12: {=INDEX('KALENDER MINGGU'!$C$6:$C$21,V12)} -> 46253 | AB12: =IF(AND($U12<=1,$V12>=1),"■","") -> ■ | AC12: =IF(AND($U12<=2,$V12>=2),"■","") -> ■ | AD12: =IF(AND($U12<=3,$V12>=3),"■","") -> ■ | AE12: =IF(AND($U12<=4,$V12>=4),"■","") -> ■ | AF12: =IF(AND($U12<=5,$V12>=5),"■","") | AG12: =IF(AND($U12<=6,$V12>=6),"■","") | AH12: =IF(AND($U12<=7,$V12>=7),"■","") | AI12: =IF(AND($U12<=8,$V12>=8),"■","") | AJ12: =IF(AND($U12<=9,$V12>=9),"■","") | AK12: =IF(AND($U12<=10,$V12>=10),"■","") | AL12: =IF(AND($U12<=11,$V12>=11),"■","") | AM12: =IF(AND($U12<=12,$V12>=12),"■","") | AN12: =IF(AND($U12<=13,$V12>=13),"■","") | AO12: =IF(AND($U12<=14,$V12>=14),"■","") | AP12: =IF(AND($U12<=15,$V12>=15),"■","") | AQ12: =IF(AND($U12<=16,$V12>=16),"■","") | AR12: A-4
B13: 5 | C13: Skafolding dan Alat Bantu Pekerjaan | D13: Sewa Skafolding 40 set Selama 2 bulan | E13: 1 | F13: Is | G13: 15000000 | H13: =E13*G13 -> 15000000 | I13: 3908731694 | J13: =H13/I13*100 -> 0.38375619 | U13: 1 | V13: 6 | W13: =MAX(1,V13-U13+1) -> 6 | X13: {=INDEX('KALENDER MINGGU'!$B$6:$B$21,U13)} -> 46226 | Y13: {=INDEX('KALENDER MINGGU'!$C$6:$C$21,V13)} -> 46267 | AB13: =IF(AND($U13<=1,$V13>=1),"■","") -> ■ | AC13: =IF(AND($U13<=2,$V13>=2),"■","") -> ■ | AD13: =IF(AND($U13<=3,$V13>=3),"■","") -> ■ | AE13: =IF(AND($U13<=4,$V13>=4),"■","") -> ■ | AF13: =IF(AND($U13<=5,$V13>=5),"■","") -> ■ | AG13: =IF(AND($U13<=6,$V13>=6),"■","") -> ■ | AH13: =IF(AND($U13<=7,$V13>=7),"■","") | AI13: =IF(AND($U13<=8,$V13>=8),"■","") | AJ13: =IF(AND($U13<=9,$V13>=9),"■","") | AK13: =IF(AND($U13<=10,$V13>=10),"■","") | AL13: =IF(AND($U13<=11,$V13>=11),"■","") | AM13: =IF(AND($U13<=12,$V13>=12),"■","") | AN13: =IF(AND($U13<=13,$V13>=13),"■","") | AO13: =IF(AND($U13<=14,$V13>=14),"■","") | AP13: =IF(AND($U13<=15,$V13>=15),"■","") | AQ13: =IF(AND($U13<=16,$V13>=16),"■","") | AR13: A-5
H14: =SUM(H8:H13) -> 50000000 | I14: 3908731694 | J14: =H14/I14*100 -> 1.2791873 | K14: B | L14: Pekerjaan Struktur - pondasi | U14: =MIN(U9:U13) -> 1 | V14: =MAX(V9:V13) -> 6 | W14: =MAX(1,V14-U14+1) -> 6 | X14: {=INDEX('KALENDER MINGGU'!$B$6:$B$21,U14)} -> 46226 | Y14: {=INDEX('KALENDER MINGGU'!$C$6:$C$21,V14)} -> 46267 | Z14: =SUM(TS!M14:AB14)/TS!L13*100 -> 100 | AA14: =IF(Z14>=99.9,"COMPLETED",IF(U14>'RENCANA MINGGUAN'!$J$7,"NOT STARTED",IF(V14<'RENCANA MINGGUAN'!$J$7,"CRITICAL",IF(Z14+1<W14,"DELAYED","ON SCHEDULE")))) -> COMPLETED | AB14: =IF(AND(U14<=1,V14>=1),"■","") -> ■ | AC14: =IF(AND(U14<=2,V14>=2),"■","") -> ■ | AD14: =IF(AND(U14<=3,V14>=3),"■","") -> ■ | AE14: =IF(AND(U14<=4,V14>=4),"■","") -> ■ | AF14: =IF(AND(U14<=5,V14>=5),"■","") -> ■ | AG14: =IF(AND(U14<=6,V14>=6),"■","") -> ■ | AH14: =IF(AND(U14<=7,V14>=7),"■","") | AI14: =IF(AND(U14<=8,V14>=8),"■","") | AJ14: =IF(AND(U14<=9,V14>=9),"■","") | AK14: =IF(AND(U14<=10,V14>=10),"■","") | AL14: =IF(AND(U14<=11,V14>=11),"■","") | AM14: =IF(AND(U14<=12,V14>=12),"■","") | AN14: =IF(AND(U14<=13,V14>=13),"■","") | AO14: =IF(AND(U14<=14,V14>=14),"■","") | AP14: =IF(AND(U14<=15,V14>=15),"■","") | AQ14: =IF(AND(U14<=16,V14>=16),"■","")
B15: B | C15: PEKERJAAN AREA GUDANG UMUM+GUDANG SPM UK.46X54 M
B16: 1 | C16: Pekerjaan Bak Kontrol | D16: Rangka siku 40x40x3mm + besi beton | E16: 4 | F16: unit | G16: 650000 | H16: =E16*G16 -> 2600000 | I16: 3908731694 | J16: =H16/I16*100 -> 0.06651774 | U16: 7 | V16: 9 | W16: =MAX(1,V16-U16+1) -> 3 | X16: {=INDEX('KALENDER MINGGU'!$B$6:$B$21,U16)} -> 46268 | Y16: {=INDEX('KALENDER MINGGU'!$C$6:$C$21,V16)} -> 46288 | AB16: =IF(AND($U16<=1,$V16>=1),"■","") | AC16: =IF(AND($U16<=2,$V16>=2),"■","") | AD16: =IF(AND($U16<=3,$V16>=3),"■","") | AE16: =IF(AND($U16<=4,$V16>=4),"■","") | AF16: =IF(AND($U16<=5,$V16>=5),"■","") | AG16: =IF(AND($U16<=6,$V16>=6),"■","") | AH16: =IF(AND($U16<=7,$V16>=7),"■","") -> ■ | AI16: =IF(AND($U16<=8,$V16>=8),"■","") -> ■ | AJ16: =IF(AND($U16<=9,$V16>=9),"■","") -> ■ | AK16: =IF(AND($U16<=10,$V16>=10),"■","") | AL16: =IF(AND($U16<=11,$V16>=11),"■","") | AM16: =IF(AND($U16<=12,$V16>=12),"■","") | AN16: =IF(AND($U16<=13,$V16>=13),"■","") | AO16: =IF(AND($U16<=14,$V16>=14),"■","") | AP16: =IF(AND($U16<=15,$V16>=15),"■","") | AQ16: =IF(AND($U16<=16,$V16>=16),"■","") | AR16: B-1
B17: 2 | C17: Pasang aluminium bubble dibawah atap+plat strip | D17: Aluminium bubble tebal 10 mm + plat strip 2mm x 3cm | E17: 2875 | F17: m² | G17: 120000 | H17: =E17*G17 -> 345000000 | I17: 3908731694 | J17: =H17/I17*100 -> 8.8263925 | U17: 6 | V17: 9 | W17: =MAX(1,V17-U17+1) -> 4 | X17: {=INDEX('KALENDER MINGGU'!$B$6:$B$21,U17)} -> 46261 | Y17: {=INDEX('KALENDER MINGGU'!$C$6:$C$21,V17)} -> 46288 | AB17: =IF(AND($U17<=1,$V17>=1),"■","") | AC17: =IF(AND($U17<=2,$V17>=2),"■","") | AD17: =IF(AND($U17<=3,$V17>=3),"■","") | AE17: =IF(AND($U17<=4,$V17>=4),"■","") | AF17: =IF(AND($U17<=5,$V17>=5),"■","") | AG17: =IF(AND($U17<=6,$V17>=6),"■","") -> ■ | AH17: =IF(AND($U17<=7,$V17>=7),"■","") -> ■ | AI17: =IF(AND($U17<=8,$V17>=8),"■","") -> ■ | AJ17: =IF(AND($U17<=9,$V17>=9),"■","") -> ■ | AK17: =IF(AND($U17<=10,$V17>=10),"■","") | AL17: =IF(AND($U17<=11,$V17>=11),"■","") | AM17: =IF(AND($U17<=12,$V17>=12),"■","") | AN17: =IF(AND($U17<=13,$V17>=13),"■","") | AO17: =IF(AND($U17<=14,$V17>=14),"■","") | AP17: =IF(AND($U17<=15,$V17>=15),"■","") | AQ17: =IF(AND($U17<=16,$V17>=16),"■","") | AR17: B-2
B18: 3 | C18: Pekerjaan finishing cat sisi luar samping dan belakang | D18: Cat dinding exterior ex. Dulux Catylac setara | E18: 1230 | F18: m² | G18: 57500 | H18: =E18*G18 -> 70725000 | I18: 3908731694 | J18: =H18/I18*100 -> 1.8094105 | U18: 7 | V18: 9 | W18: =MAX(1,V18-U18+1) -> 3 | X18: {=INDEX('KALENDER MINGGU'!$B$6:$B$21,U18)} -> 46268 | Y18: {=INDEX('KALENDER MINGGU'!$C$6:$C$21,V18)} -> 46288 | AB18: =IF(AND($U18<=1,$V18>=1),"■","") | AC18: =IF(AND($U18<=2,$V18>=2),"■","") | AD18: =IF(AND($U18<=3,$V18>=3),"■","") | AE18: =IF(AND($U18<=4,$V18>=4),"■","") | AF18: =IF(AND($U18<=5,$V18>=5),"■","") | AG18: =IF(AND($U18<=6,$V18>=6),"■","") | AH18: =IF(AND($U18<=7,$V18>=7),"■","") -> ■ | AI18: =IF(AND($U18<=8,$V18>=8),"■","") -> ■ | AJ18: =IF(AND($U18<=9,$V18>=9),"■","") -> ■ | AK18: =IF(AND($U18<=10,$V18>=10),"■","") | AL18: =IF(AND($U18<=11,$V18>=11),"■","") | AM18: =IF(AND($U18<=12,$V18>=12),"■","") | AN18: =IF(AND($U18<=13,$V18>=13),"■","") | AO18: =IF(AND($U18<=14,$V18>=14),"■","") | AP18: =IF(AND($U18<=15,$V18>=15),"■","") | AQ18: =IF(AND($U18<=16,$V18>=16),"■","") | AR18: B-3
B19: 4 | C19: Pasang turbin ventilator 32" | D19: Turbin Ventilator 32 " | E19: 18 | F19: unit | G19: 2500000 | H19: =E19*G19 -> 45000000 | I19: 3908731694 | J19: =H19/I19*100 -> 1.1512686 | U19: 7 | V19: 9 | W19: =MAX(1,V19-U19+1) -> 3 | X19: {=INDEX('KALENDER MINGGU'!$B$6:$B$21,U19)} -> 46268 | Y19: {=INDEX('KALENDER MINGGU'!$C$6:$C$21,V19)} -> 46288 | AB19: =IF(AND($U19<=1,$V19>=1),"■","") | AC19: =IF(AND($U19<=2,$V19>=2),"■","") | AD19: =IF(AND($U19<=3,$V19>=3),"■","") | AE19: =IF(AND($U19<=4,$V19>=4),"■","") | AF19: =IF(AND($U19<=5,$V19>=5),"■","") | AG19: =IF(AND($U19<=6,$V19>=6),"■","") | AH19: =IF(AND($U19<=7,$V19>=7),"■","") -> ■ | AI19: =IF(AND($U19<=8,$V19>=8),"■","") -> ■ | AJ19: =IF(AND($U19<=9,$V19>=9),"■","") -> ■ | AK19: =IF(AND($U19<=10,$V19>=10),"■","") | AL19: =IF(AND($U19<=11,$V19>=11),"■","") | AM19: =IF(AND($U19<=12,$V19>=12),"■","") | AN19: =IF(AND($U19<=13,$V19>=13),"■","") | AO19: =IF(AND($U19<=14,$V19>=14),"■","") | AP19: =IF(AND($U19<=15,$V19>=15),"■","") | AQ19: =IF(AND($U19<=16,$V19>=16),"■","") | AR19: B-4
B20: 5 | C20: Bongkar atap existing | D20: diganti bening | E20: 196 | F20: m² | G20: 25000 | H20: =E20*G20 -> 4900000 | I20: 3908731694 | J20: =H20/I20*100 -> 0.12536036 | U20: 7 | V20: 9 | W20: =MAX(1,V20-U20+1) -> 3 | X20: {=INDEX('KALENDER MINGGU'!$B$6:$B$21,U20)} -> 46268 | Y20: {=INDEX('KALENDER MINGGU'!$C$6:$C$21,V20)} -> 46288 | AB20: =IF(AND($U20<=1,$V20>=1),"■","") | AC20: =IF(AND($U20<=2,$V20>=2),"■","") | AD20: =IF(AND($U20<=3,$V20>=3),"■","") | AE20: =IF(AND($U20<=4,$V20>=4),"■","") | AF20: =IF(AND($U20<=5,$V20>=5),"■","") | AG20: =IF(AND($U20<=6,$V20>=6),"■","") | AH20: =IF(AND($U20<=7,$V20>=7),"■","") -> ■ | AI20: =IF(AND($U20<=8,$V20>=8),"■","") -> ■ | AJ20: =IF(AND($U20<=9,$V20>=9),"■","") -> ■ | AK20: =IF(AND($U20<=10,$V20>=10),"■","") | AL20: =IF(AND($U20<=11,$V20>=11),"■","") | AM20: =IF(AND($U20<=12,$V20>=12),"■","") | AN20: =IF(AND($U20<=13,$V20>=13),"■","") | AO20: =IF(AND($U20<=14,$V20>=14),"■","") | AP20: =IF(AND($U20<=15,$V20>=15),"■","") | AQ20: =IF(AND($U20<=16,$V20>=16),"■","") | AR20: B-5
B21: 6 | C21: Pasang atap fiber bening | D21: Fiber bening ex. Clandianplast Setara | E21: 196 | F21: m² | G21: 143000 | H21: =E21*G21 -> 28028000 | I21: 3908731694 | J21: =H21/I21*100 -> 0.71706124 | U21: 7 | V21: 9 | W21: =MAX(1,V21-U21+1) -> 3 | X21: {=INDEX('KALENDER MINGGU'!$B$6:$B$21,U21)} -> 46268 | Y21: {=INDEX('KALENDER MINGGU'!$C$6:$C$21,V21)} -> 46288 | AB21: =IF(AND($U21<=1,$V21>=1),"■","") | AC21: =IF(AND($U21<=2,$V21>=2),"■","") | AD21: =IF(AND($U21<=3,$V21>=3),"■","") | AE21: =IF(AND($U21<=4,$V21>=4),"■","") | AF21: =IF(AND($U21<=5,$V21>=5),"■","") | AG21: =IF(AND($U21<=6,$V21>=6),"■","") | AH21: =IF(AND($U21<=7,$V21>=7),"■","") -> ■ | AI21: =IF(AND($U21<=8,$V21>=8),"■","") -> ■ | AJ21: =IF(AND($U21<=9,$V21>=9),"■","") -> ■ | AK21: =IF(AND($U21<=10,$V21>=10),"■","") | AL21: =IF(AND($U21<=11,$V21>=11),"■","") | AM21: =IF(AND($U21<=12,$V21>=12),"■","") | AN21: =IF(AND($U21<=13,$V21>=13),"■","") | AO21: =IF(AND($U21<=14,$V21>=14),"■","") | AP21: =IF(AND($U21<=15,$V21>=15),"■","") | AQ21: =IF(AND($U21<=16,$V21>=16),"■","") | AR21: B-6
B22: 7 | C22: pekerjaan refinishing kanopi loading dock | D22: Cat Ftalit Royal Blue | E22: 290 | F22: m² | G22: 85000 | H22: =E22*G22 -> 24650000 | I22: 3908731694 | J22: =H22/I22*100 -> 0.63063935 | U22: 7 | V22: 9 | W22: =MAX(1,V22-U22+1) -> 3 | X22: {=INDEX('KALENDER MINGGU'!$B$6:$B$21,U22)} -> 46268 | Y22: {=INDEX('KALENDER MINGGU'!$C$6:$C$21,V22)} -> 46288 | AB22: =IF(AND($U22<=1,$V22>=1),"■","") | AC22: =IF(AND($U22<=2,$V22>=2),"■","") | AD22: =IF(AND($U22<=3,$V22>=3),"■","") | AE22: =IF(AND($U22<=4,$V22>=4),"■","") | AF22: =IF(AND($U22<=5,$V22>=5),"■","") | AG22: =IF(AND($U22<=6,$V22>=6),"■","") | AH22: =IF(AND($U22<=7,$V22>=7),"■","") -> ■ | AI22: =IF(AND($U22<=8,$V22>=8),"■","") -> ■ | AJ22: =IF(AND($U22<=9,$V22>=9),"■","") -> ■ | AK22: =IF(AND($U22<=10,$V22>=10),"■","") | AL22: =IF(AND($U22<=11,$V22>=11),"■","") | AM22: =IF(AND($U22<=12,$V22>=12),"■","") | AN22: =IF(AND($U22<=13,$V22>=13),"■","") | AO22: =IF(AND($U22<=14,$V22>=14),"■","") | AP22: =IF(AND($U22<=15,$V22>=15),"■","") | AQ22: =IF(AND($U22<=16,$V22>=16),"■","") | AR22: B-7
B23: 8 | C23: Perbaikan loading dock | D23: Penambahan besi siku 70 x 70 mm | E23: 45 | F23: m | G23: 344500 | H23: =E23*G23 -> 15502500 | I23: 3908731694 | J23: =H23/I23*100 -> 0.39661203 | U23: 8 | V23: 9 | W23: =MAX(1,V23-U23+1) -> 2 | X23: {=INDEX('KALENDER MINGGU'!$B$6:$B$21,U23)} -> 46275 | Y23: {=INDEX('KALENDER MINGGU'!$C$6:$C$21,V23)} -> 46288 | AB23: =IF(AND($U23<=1,$V23>=1),"■","") | AC23: =IF(AND($U23<=2,$V23>=2),"■","") | AD23: =IF(AND($U23<=3,$V23>=3),"■","") | AE23: =IF(AND($U23<=4,$V23>=4),"■","") | AF23: =IF(AND($U23<=5,$V23>=5),"■","") | AG23: =IF(AND($U23<=6,$V23>=6),"■","") | AH23: =IF(AND($U23<=7,$V23>=7),"■","") | AI23: =IF(AND($U23<=8,$V23>=8),"■","") -> ■ | AJ23: =IF(AND($U23<=9,$V23>=9),"■","") -> ■ | AK23: =IF(AND($U23<=10,$V23>=10),"■","") | AL23: =IF(AND($U23<=11,$V23>=11),"■","") | AM23: =IF(AND($U23<=12,$V23>=12),"■","") | AN23: =IF(AND($U23<=13,$V23>=13),"■","") | AO23: =IF(AND($U23<=14,$V23>=14),"■","") | AP23: =IF(AND($U23<=15,$V23>=15),"■","") | AQ23: =IF(AND($U23<=16,$V23>=16),"■","") | AR23: B-8
B24: 9 | C24: Perbaikan dinding dan cat dinding loading dock | D24: Cat dinding exterior ex. Dulux Catylac setara | E24: 37 | F24: m | G24: 57500 | H24: =E24*G24 -> 2127500 | I24: 3908731694 | J24: =H24/I24*100 -> 0.05442942 | U24: 8 | V24: 9 | W24: =MAX(1,V24-U24+1) -> 2 | X24: {=INDEX('KALENDER MINGGU'!$B$6:$B$21,U24)} -> 46275 | Y24: {=INDEX('KALENDER MINGGU'!$C$6:$C$21,V24)} -> 46288 | AB24: =IF(AND($U24<=1,$V24>=1),"■","") | AC24: =IF(AND($U24<=2,$V24>=2),"■","") | AD24: =IF(AND($U24<=3,$V24>=3),"■","") | AE24: =IF(AND($U24<=4,$V24>=4),"■","") | AF24: =IF(AND($U24<=5,$V24>=5),"■","") | AG24: =IF(AND($U24<=6,$V24>=6),"■","") | AH24: =IF(AND($U24<=7,$V24>=7),"■","") | AI24: =IF(AND($U24<=8,$V24>=8),"■","") -> ■ | AJ24: =IF(AND($U24<=9,$V24>=9),"■","") -> ■ | AK24: =IF(AND($U24<=10,$V24>=10),"■","") | AL24: =IF(AND($U24<=11,$V24>=11),"■","") | AM24: =IF(AND($U24<=12,$V24>=12),"■","") | AN24: =IF(AND($U24<=13,$V24>=13),"■","") | AO24: =IF(AND($U24<=14,$V24>=14),"■","") | AP24: =IF(AND($U24<=15,$V24>=15),"■","") | AQ24: =IF(AND($U24<=16,$V24>=16),"■","") | AR24: B-9
B25: 10 | C25: Servis kebocoran pipa talang | E25: 1 | F25: ls | G25: 5200000 | H25: =E25*G25 -> 5200000 | I25: 3908731694 | J25: =H25/I25*100 -> 0.13303548 | U25: 7 | V25: 9 | W25: =MAX(1,V25-U25+1) -> 3 | X25: {=INDEX('KALENDER MINGGU'!$B$6:$B$21,U25)} -> 46268 | Y25: {=INDEX('KALENDER MINGGU'!$C$6:$C$21,V25)} -> 46288 | AB25: =IF(AND($U25<=1,$V25>=1),"■","") | AC25: =IF(AND($U25<=2,$V25>=2),"■","") | AD25: =IF(AND($U25<=3,$V25>=3),"■","") | AE25: =IF(AND($U25<=4,$V25>=4),"■","") | AF25: =IF(AND($U25<=5,$V25>=5),"■","") | AG25: =IF(AND($U25<=6,$V25>=6),"■","") | AH25: =IF(AND($U25<=7,$V25>=7),"■","") -> ■ | AI25: =IF(AND($U25<=8,$V25>=8),"■","") -> ■ | AJ25: =IF(AND($U25<=9,$V25>=9),"■","") -> ■ | AK25: =IF(AND($U25<=10,$V25>=10),"■","") | AL25: =IF(AND($U25<=11,$V25>=11),"■","") | AM25: =IF(AND($U25<=12,$V25>=12),"■","") | AN25: =IF(AND($U25<=13,$V25>=13),"■","") | AO25: =IF(AND($U25<=14,$V25>=14),"■","") | AP25: =IF(AND($U25<=15,$V25>=15),"■","") | AQ25: =IF(AND($U25<=16,$V25>=16),"■","") | AR25: B-10
B26: 11 | C26: Cor ulang lantai gudang utama sisi pintu dalam (4mx5m) | D26: inc kupas, pembesian M8, cor | E26: 60 | F26: m² | G26: 1100000 | H26: =E26*G26 -> 66000000 | I26: 3908731694 | J26: =H26/I26*100 -> 1.6885273 | U26: 9 | V26: 11 | W26: =MAX(1,V26-U26+1) -> 3 | X26: {=INDEX('KALENDER MINGGU'!$B$6:$B$21,U26)} -> 46282 | Y26: {=INDEX('KALENDER MINGGU'!$C$6:$C$21,V26)} -> 46302 | AB26: =IF(AND($U26<=1,$V26>=1),"■","") | AC26: =IF(AND($U26<=2,$V26>=2),"■","") | AD26: =IF(AND($U26<=3,$V26>=3),"■","") | AE26: =IF(AND($U26<=4,$V26>=4),"■","") | AF26: =IF(AND($U26<=5,$V26>=5),"■","") | AG26: =IF(AND($U26<=6,$V26>=6),"■","") | AH26: =IF(AND($U26<=7,$V26>=7),"■","") | AI26: =IF(AND($U26<=8,$V26>=8),"■","") | AJ26: =IF(AND($U26<=9,$V26>=9),"■","") -> ■ | AK26: =IF(AND($U26<=10,$V26>=10),"■","") -> ■ | AL26: =IF(AND($U26<=11,$V26>=11),"■","") -> ■ | AM26: =IF(AND($U26<=12,$V26>=12),"■","") | AN26: =IF(AND($U26<=13,$V26>=13),"■","") | AO26: =IF(AND($U26<=14,$V26>=14),"■","") | AP26: =IF(AND($U26<=15,$V26>=15),"■","") | AQ26: =IF(AND($U26<=16,$V26>=16),"■","") | AR26: B-11
B27: 12 | C27: Pembongkaran pintu rolling door | D27: inc buang | E27: 1 | F27: ls | G27: 2500000 | H27: =E27*G27 -> 2500000 | I27: 3908731694 | J27: =H27/I27*100 -> 0.063959366 | U27: 8 | V27: 9 | W27: =MAX(1,V27-U27+1) -> 2 | X27: {=INDEX('KALENDER MINGGU'!$B$6:$B$21,U27)} -> 46275 | Y27: {=INDEX('KALENDER MINGGU'!$C$6:$C$21,V27)} -> 46288 | AB27: =IF(AND($U27<=1,$V27>=1),"■","") | AC27: =IF(AND($U27<=2,$V27>=2),"■","") | AD27: =IF(AND($U27<=3,$V27>=3),"■","") | AE27: =IF(AND($U27<=4,$V27>=4),"■","") | AF27: =IF(AND($U27<=5,$V27>=5),"■","") | AG27: =IF(AND($U27<=6,$V27>=6),"■","") | AH27: =IF(AND($U27<=7,$V27>=7),"■","") | AI27: =IF(AND($U27<=8,$V27>=8),"■","") -> ■ | AJ27: =IF(AND($U27<=9,$V27>=9),"■","") -> ■ | AK27: =IF(AND($U27<=10,$V27>=10),"■","") | AL27: =IF(AND($U27<=11,$V27>=11),"■","") | AM27: =IF(AND($U27<=12,$V27>=12),"■","") | AN27: =IF(AND($U27<=13,$V27>=13),"■","") | AO27: =IF(AND($U27<=14,$V27>=14),"■","") | AP27: =IF(AND($U27<=15,$V27>=15),"■","") | AQ27: =IF(AND($U27<=16,$V27>=16),"■","") | AR27: B-12
B28: 13 | C28: Perapian kabel dalam gudang | D28: cable tray custom | E28: 54 | F28: m | G28: 360000 | H28: =E28*G28 -> 19440000 | I28: 3908731694 | J28: =H28/I28*100 -> 0.49734803 | U28: 8 | V28: 10 | W28: =MAX(1,V28-U28+1) -> 3 | X28: {=INDEX('KALENDER MINGGU'!$B$6:$B$21,U28)} -> 46275 | Y28: {=INDEX('KALENDER MINGGU'!$C$6:$C$21,V28)} -> 46295 | AB28: =IF(AND($U28<=1,$V28>=1),"■","") | AC28: =IF(AND($U28<=2,$V28>=2),"■","") | AD28: =IF(AND($U28<=3,$V28>=3),"■","") | AE28: =IF(AND($U28<=4,$V28>=4),"■","") | AF28: =IF(AND($U28<=5,$V28>=5),"■","") | AG28: =IF(AND($U28<=6,$V28>=6),"■","") | AH28: =IF(AND($U28<=7,$V28>=7),"■","") | AI28: =IF(AND($U28<=8,$V28>=8),"■","") -> ■ | AJ28: =IF(AND($U28<=9,$V28>=9),"■","") -> ■ | AK28: =IF(AND($U28<=10,$V28>=10),"■","") -> ■ | AL28: =IF(AND($U28<=11,$V28>=11),"■","") | AM28: =IF(AND($U28<=12,$V28>=12),"■","") | AN28: =IF(AND($U28<=13,$V28>=13),"■","") | AO28: =IF(AND($U28<=14,$V28>=14),"■","") | AP28: =IF(AND($U28<=15,$V28>=15),"■","") | AQ28: =IF(AND($U28<=16,$V28>=16),"■","") | AR28: B-13
H29: =SUM(H16:H28) -> 631673000 | I29: 3908731694 | J29: =H29/I29*100 -> 16.160562 | U29: =MIN(U16:U28) -> 6 | V29: =MAX(V16:V28) -> 11 | W29: =MAX(1,V29-U29+1) -> 6 | X29: {=INDEX('KALENDER MINGGU'!$B$6:$B$21,U29)} -> 46261 | Y29: {=INDEX('KALENDER MINGGU'!$C$6:$C$21,V29)} -> 46302 | Z29: =SUM(TS!M16:AB16)/TS!L15*100 -> 40.815184 | AA29: =IF(Z29>=99.9,"COMPLETED",IF(U29>'RENCANA MINGGUAN'!$J$7,"NOT STARTED",IF(V29<'RENCANA MINGGUAN'!$J$7,"CRITICAL",IF(Z29+1<W29,"DELAYED","ON SCHEDULE")))) -> ON SCHEDULE | AB29: =IF(AND(U29<=1,V29>=1),"■","") | AC29: =IF(AND(U29<=2,V29>=2),"■","") | AD29: =IF(AND(U29<=3,V29>=3),"■","") | AE29: =IF(AND(U29<=4,V29>=4),"■","") | AF29: =IF(AND(U29<=5,V29>=5),"■","") | AG29: =IF(AND(U29<=6,V29>=6),"■","") -> ■ | AH29: =IF(AND(U29<=7,V29>=7),"■","") -> ■ | AI29: =IF(AND(U29<=8,V29>=8),"■","") -> ■ | AJ29: =IF(AND(U29<=9,V29>=9),"■","") -> ■ | AK29: =IF(AND(U29<=10,V29>=10),"■","") -> ■ | AL29: =IF(AND(U29<=11,V29>=11),"■","") -> ■ | AM29: =IF(AND(U29<=12,V29>=12),"■","") | AN29: =IF(AND(U29<=13,V29>=13),"■","") | AO29: =IF(AND(U29<=14,V29>=14),"■","") | AP29: =IF(AND(U29<=15,V29>=15),"■","") | AQ29: =IF(AND(U29<=16,V29>=16),"■","")
H30: =E30*G30 -> 0
B31: C | C31: PEKERJAAN AREA GUDANG PARKIR SISI SAMPING UK.4,75X37M | H31: =E31*G31 -> 0
B32: 1 | C32: Perbaikan atap existing | E32: 30 | F32: m² | G32: 40000 | H32: =E32*G32 -> 1200000 | I32: 3908731694 | J32: =H32/I32*100 -> 0.030700496 | U32: 9 | V32: 10 | W32: =MAX(1,V32-U32+1) -> 2 | X32: {=INDEX('KALENDER MINGGU'!$B$6:$B$21,U32)} -> 46282 | Y32: {=INDEX('KALENDER MINGGU'!$C$6:$C$21,V32)} -> 46295 | AB32: =IF(AND($U32<=1,$V32>=1),"■","") | AC32: =IF(AND($U32<=2,$V32>=2),"■","") | AD32: =IF(AND($U32<=3,$V32>=3),"■","") | AE32: =IF(AND($U32<=4,$V32>=4),"■","") | AF32: =IF(AND($U32<=5,$V32>=5),"■","") | AG32: =IF(AND($U32<=6,$V32>=6),"■","") | AH32: =IF(AND($U32<=7,$V32>=7),"■","") | AI32: =IF(AND($U32<=8,$V32>=8),"■","") | AJ32: =IF(AND($U32<=9,$V32>=9),"■","") -> ■ | AK32: =IF(AND($U32<=10,$V32>=10),"■","") -> ■ | AL32: =IF(AND($U32<=11,$V32>=11),"■","") | AM32: =IF(AND($U32<=12,$V32>=12),"■","") | AN32: =IF(AND($U32<=13,$V32>=13),"■","") | AO32: =IF(AND($U32<=14,$V32>=14),"■","") | AP32: =IF(AND($U32<=15,$V32>=15),"■","") | AQ32: =IF(AND($U32<=16,$V32>=16),"■","") | AR32: C-1
B33: 2 | C33: Pekerjaan bongkaran lantai paving block existing | D33: Termasuk pembuangan bekas bongkaran | E33: 105 | F33: m² | G33: 35000 | H33: =E33*G33 -> 3675000 | I33: 3908731694 | J33: =H33/I33*100 -> 0.094020268 | U33: 7 | V33: 9 | W33: =MAX(1,V33-U33+1) -> 3 | X33: {=INDEX('KALENDER MINGGU'!$B$6:$B$21,U33)} -> 46268 | Y33: {=INDEX('KALENDER MINGGU'!$C$6:$C$21,V33)} -> 46288 | AB33: =IF(AND($U33<=1,$V33>=1),"■","") | AC33: =IF(AND($U33<=2,$V33>=2),"■","") | AD33: =IF(AND($U33<=3,$V33>=3),"■","") | AE33: =IF(AND($U33<=4,$V33>=4),"■","") | AF33: =IF(AND($U33<=5,$V33>=5),"■","") | AG33: =IF(AND($U33<=6,$V33>=6),"■","") | AH33: =IF(AND($U33<=7,$V33>=7),"■","") -> ■ | AI33: =IF(AND($U33<=8,$V33>=8),"■","") -> ■ | AJ33: =IF(AND($U33<=9,$V33>=9),"■","") -> ■ | AK33: =IF(AND($U33<=10,$V33>=10),"■","") | AL33: =IF(AND($U33<=11,$V33>=11),"■","") | AM33: =IF(AND($U33<=12,$V33>=12),"■","") | AN33: =IF(AND($U33<=13,$V33>=13),"■","") | AO33: =IF(AND($U33<=14,$V33>=14),"■","") | AP33: =IF(AND($U33<=15,$V33>=15),"■","") | AQ33: =IF(AND($U33<=16,$V33>=16),"■","") | AR33: C-2
B34: 3 | C34: Pekerjaan pasang rangka kolom dan atap area parkir + penutup + talang | D34: Rangka menggunakan besi CNP 100 double+talang+cat ftalit royal blue+atap zincalum 0,3 mm ex. Kencana | E34: 40 | F34: m² | G34: 275000 | H34: =E34*G34 -> 11000000 | I34: 3908731694 | J34: =H34/I34*100 -> 0.28142121 | U34: 7 | V34: 9 | W34: =MAX(1,V34-U34+1) -> 3 | X34: {=INDEX('KALENDER MINGGU'!$B$6:$B$21,U34)} -> 46268 | Y34: {=INDEX('KALENDER MINGGU'!$C$6:$C$21,V34)} -> 46288 | AB34: =IF(AND($U34<=1,$V34>=1),"■","") | AC34: =IF(AND($U34<=2,$V34>=2),"■","") | AD34: =IF(AND($U34<=3,$V34>=3),"■","") | AE34: =IF(AND($U34<=4,$V34>=4),"■","") | AF34: =IF(AND($U34<=5,$V34>=5),"■","") | AG34: =IF(AND($U34<=6,$V34>=6),"■","") | AH34: =IF(AND($U34<=7,$V34>=7),"■","") -> ■ | AI34: =IF(AND($U34<=8,$V34>=8),"■","") -> ■ | AJ34: =IF(AND($U34<=9,$V34>=9),"■","") -> ■ | AK34: =IF(AND($U34<=10,$V34>=10),"■","") | AL34: =IF(AND($U34<=11,$V34>=11),"■","") | AM34: =IF(AND($U34<=12,$V34>=12),"■","") | AN34: =IF(AND($U34<=13,$V34>=13),"■","") | AO34: =IF(AND($U34<=14,$V34>=14),"■","") | AP34: =IF(AND($U34<=15,$V34>=15),"■","") | AQ34: =IF(AND($U34<=16,$V34>=16),"■","") | AR34: C-3
B35: 4 | C35: Pemasangan atap transparan di area tambahan | D35: polycarbonate transparan | E35: 14 | F35: m² | G35: 160000 | H35: =E35*G35 -> 2240000 | I35: 3908731694 | J35: =H35/I35*100 -> 0.057307592 | U35: 7 | V35: 9 | W35: =MAX(1,V35-U35+1) -> 3 | X35: {=INDEX('KALENDER MINGGU'!$B$6:$B$21,U35)} -> 46268 | Y35: {=INDEX('KALENDER MINGGU'!$C$6:$C$21,V35)} -> 46288 | AB35: =IF(AND($U35<=1,$V35>=1),"■","") | AC35: =IF(AND($U35<=2,$V35>=2),"■","") | AD35: =IF(AND($U35<=3,$V35>=3),"■","") | AE35: =IF(AND($U35<=4,$V35>=4),"■","") | AF35: =IF(AND($U35<=5,$V35>=5),"■","") | AG35: =IF(AND($U35<=6,$V35>=6),"■","") | AH35: =IF(AND($U35<=7,$V35>=7),"■","") -> ■ | AI35: =IF(AND($U35<=8,$V35>=8),"■","") -> ■ | AJ35: =IF(AND($U35<=9,$V35>=9),"■","") -> ■ | AK35: =IF(AND($U35<=10,$V35>=10),"■","") | AL35: =IF(AND($U35<=11,$V35>=11),"■","") | AM35: =IF(AND($U35<=12,$V35>=12),"■","") | AN35: =IF(AND($U35<=13,$V35>=13),"■","") | AO35: =IF(AND($U35<=14,$V35>=14),"■","") | AP35: =IF(AND($U35<=15,$V35>=15),"■","") | AQ35: =IF(AND($U35<=16,$V35>=16),"■","") | AR35: C-4
B36: 5 | C36: Pemadatan dan peninggian lantai parkir | D36: Peninggian dengan pasir 10cm + pemadatan | E36: 185 | F36: m² | G36: 150000 | H36: =E36*G36 -> 27750000 | I36: 3908731694 | J36: =H36/I36*100 -> 0.70994896 | U36: 7 | V36: 10 | W36: =MAX(1,V36-U36+1) -> 4 | X36: {=INDEX('KALENDER MINGGU'!$B$6:$B$21,U36)} -> 46268 | Y36: {=INDEX('KALENDER MINGGU'!$C$6:$C$21,V36)} -> 46295 | AB36: =IF(AND($U36<=1,$V36>=1),"■","") | AC36: =IF(AND($U36<=2,$V36>=2),"■","") | AD36: =IF(AND($U36<=3,$V36>=3),"■","") | AE36: =IF(AND($U36<=4,$V36>=4),"■","") | AF36: =IF(AND($U36<=5,$V36>=5),"■","") | AG36: =IF(AND($U36<=6,$V36>=6),"■","") | AH36: =IF(AND($U36<=7,$V36>=7),"■","") -> ■ | AI36: =IF(AND($U36<=8,$V36>=8),"■","") -> ■ | AJ36: =IF(AND($U36<=9,$V36>=9),"■","") -> ■ | AK36: =IF(AND($U36<=10,$V36>=10),"■","") -> ■ | AL36: =IF(AND($U36<=11,$V36>=11),"■","") | AM36: =IF(AND($U36<=12,$V36>=12),"■","") | AN36: =IF(AND($U36<=13,$V36>=13),"■","") | AO36: =IF(AND($U36<=14,$V36>=14),"■","") | AP36: =IF(AND($U36<=15,$V36>=15),"■","") | AQ36: =IF(AND($U36<=16,$V36>=16),"■","") | AR36: C-5
B37: 6 | C37: Pasang paving block lantai parkir | D37: Paving blok K-150 tebal 6 cm | E37: 93 | F37: m² | G37: 185000 | H37: =E37*G37 -> 17205000 | I37: 3908731694 | J37: =H37/I37*100 -> 0.44016836 | U37: 8 | V37: 10 | W37: =MAX(1,V37-U37+1) -> 3 | X37: {=INDEX('KALENDER MINGGU'!$B$6:$B$21,U37)} -> 46275 | Y37: {=INDEX('KALENDER MINGGU'!$C$6:$C$21,V37)} -> 46295 | AB37: =IF(AND($U37<=1,$V37>=1),"■","") | AC37: =IF(AND($U37<=2,$V37>=2),"■","") | AD37: =IF(AND($U37<=3,$V37>=3),"■","") | AE37: =IF(AND($U37<=4,$V37>=4),"■","") | AF37: =IF(AND($U37<=5,$V37>=5),"■","") | AG37: =IF(AND($U37<=6,$V37>=6),"■","") | AH37: =IF(AND($U37<=7,$V37>=7),"■","") | AI37: =IF(AND($U37<=8,$V37>=8),"■","") -> ■ | AJ37: =IF(AND($U37<=9,$V37>=9),"■","") -> ■ | AK37: =IF(AND($U37<=10,$V37>=10),"■","") -> ■ | AL37: =IF(AND($U37<=11,$V37>=11),"■","") | AM37: =IF(AND($U37<=12,$V37>=12),"■","") | AN37: =IF(AND($U37<=13,$V37>=13),"■","") | AO37: =IF(AND($U37<=14,$V37>=14),"■","") | AP37: =IF(AND($U37<=15,$V37>=15),"■","") | AQ37: =IF(AND($U37<=16,$V37>=16),"■","") | AR37: C-6
B38: 7 | C38: Instalasi penerangan + downlight exposed + bohlam 12 w | D38: Kabel ex. Eterna+rumah lampu | E38: 10 | F38: unit | G38: 364000 | H38: =E38*G38 -> 3640000 | I38: 3908731694 | J38: =H38/I38*100 -> 0.093124837 | U38: 9 | V38: 10 | W38: =MAX(1,V38-U38+1) -> 2 | X38: {=INDEX('KALENDER MINGGU'!$B$6:$B$21,U38)} -> 46282 | Y38: {=INDEX('KALENDER MINGGU'!$C$6:$C$21,V38)} -> 46295 | AB38: =IF(AND($U38<=1,$V38>=1),"■","") | AC38: =IF(AND($U38<=2,$V38>=2),"■","") | AD38: =IF(AND($U38<=3,$V38>=3),"■","") | AE38: =IF(AND($U38<=4,$V38>=4),"■","") | AF38: =IF(AND($U38<=5,$V38>=5),"■","") | AG38: =IF(AND($U38<=6,$V38>=6),"■","") | AH38: =IF(AND($U38<=7,$V38>=7),"■","") | AI38: =IF(AND($U38<=8,$V38>=8),"■","") | AJ38: =IF(AND($U38<=9,$V38>=9),"■","") -> ■ | AK38: =IF(AND($U38<=10,$V38>=10),"■","") -> ■ | AL38: =IF(AND($U38<=11,$V38>=11),"■","") | AM38: =IF(AND($U38<=12,$V38>=12),"■","") | AN38: =IF(AND($U38<=13,$V38>=13),"■","") | AO38: =IF(AND($U38<=14,$V38>=14),"■","") | AP38: =IF(AND($U38<=15,$V38>=15),"■","") | AQ38: =IF(AND($U38<=16,$V38>=16),"■","") | AR38: C-7
B39: 8 | C39: Perapian kabel existing dan dinding existing | D39: Pasang kabel tray + perapian dinding | E39: 1 | F39: Is | G39: 4500000 | H39: =E39*G39 -> 4500000 | I39: 3908731694 | J39: =H39/I39*100 -> 0.11512686 | U39: 9 | V39: 10 | W39: =MAX(1,V39-U39+1) -> 2 | X39: {=INDEX('KALENDER MINGGU'!$B$6:$B$21,U39)} -> 46282 | Y39: {=INDEX('KALENDER MINGGU'!$C$6:$C$21,V39)} -> 46295 | AB39: =IF(AND($U39<=1,$V39>=1),"■","") | AC39: =IF(AND($U39<=2,$V39>=2),"■","") | AD39: =IF(AND($U39<=3,$V39>=3),"■","") | AE39: =IF(AND($U39<=4,$V39>=4),"■","") | AF39: =IF(AND($U39<=5,$V39>=5),"■","") | AG39: =IF(AND($U39<=6,$V39>=6),"■","") | AH39: =IF(AND($U39<=7,$V39>=7),"■","") | AI39: =IF(AND($U39<=8,$V39>=8),"■","") | AJ39: =IF(AND($U39<=9,$V39>=9),"■","") -> ■ | AK39: =IF(AND($U39<=10,$V39>=10),"■","") -> ■ | AL39: =IF(AND($U39<=11,$V39>=11),"■","") | AM39: =IF(AND($U39<=12,$V39>=12),"■","") | AN39: =IF(AND($U39<=13,$V39>=13),"■","") | AO39: =IF(AND($U39<=14,$V39>=14),"■","") | AP39: =IF(AND($U39<=15,$V39>=15),"■","") | AQ39: =IF(AND($U39<=16,$V39>=16),"■","") | AR39: C-8
B40: 9 | C40: Pembuatan saluran bawah paving | D40: sudetan 4" | E40: 6 | F40: Is | G40: 600000 | H40: =E40*G40 -> 3600000 | I40: 3908731694 | J40: =H40/I40*100 -> 0.092101487 | U40: 7 | V40: 9 | W40: =MAX(1,V40-U40+1) -> 3 | X40: {=INDEX('KALENDER MINGGU'!$B$6:$B$21,U40)} -> 46268 | Y40: {=INDEX('KALENDER MINGGU'!$C$6:$C$21,V40)} -> 46288 | AB40: =IF(AND($U40<=1,$V40>=1),"■","") | AC40: =IF(AND($U40<=2,$V40>=2),"■","") | AD40: =IF(AND($U40<=3,$V40>=3),"■","") | AE40: =IF(AND($U40<=4,$V40>=4),"■","") | AF40: =IF(AND($U40<=5,$V40>=5),"■","") | AG40: =IF(AND($U40<=6,$V40>=6),"■","") | AH40: =IF(AND($U40<=7,$V40>=7),"■","") -> ■ | AI40: =IF(AND($U40<=8,$V40>=8),"■","") -> ■ | AJ40: =IF(AND($U40<=9,$V40>=9),"■","") -> ■ | AK40: =IF(AND($U40<=10,$V40>=10),"■","") | AL40: =IF(AND($U40<=11,$V40>=11),"■","") | AM40: =IF(AND($U40<=12,$V40>=12),"■","") | AN40: =IF(AND($U40<=13,$V40>=13),"■","") | AO40: =IF(AND($U40<=14,$V40>=14),"■","") | AP40: =IF(AND($U40<=15,$V40>=15),"■","") | AQ40: =IF(AND($U40<=16,$V40>=16),"■","") | AR40: C-9
...

Sheet TS INTERNAL LAPANGAN
A3: TIME SCHEDULE
A4: PEKERJAAN : ARTABOGA GATSU
A5: Periode : Juli 2026 s/d Oktober 2026
A7: NO | B7: URAIAN PEKERJAAN | L7: BOBOT | M7: JULI | N7: AGUSTUS | R7: SEPTEMBER | W7: OKTOBER | AA7: KET
M8: Week 1 | N8: Week 2 | O8: Week 3 | P8: Week 4 | Q8: Week 5 | R8: Week 6 | S8: Week 7 | T8: Week 8 | U8: Week 9 | V8: Week 10 | W8: Week 11 | X8: Week 12 | Y8: Week 13 | Z8: Week 14
A9: I | B9: ='BOBOT PEK'!B5 -> 0
A10: A | B10: ='BOBOT PEK'!B6 -> No | L10: ='BOBOT PEK'!I12 -> 3908731694 | M10: =L10/2 -> 1954365847 | N10: =M10 -> 1954365847
A11: B | B11: ='BOBOT PEK'!B13 -> 5 | L11: ='BOBOT PEK'!I27 -> 3908731694 | O11: =L11/8 -> 4.8859146e+08 | P11: =O11 -> 4.8859146e+08 | Q11: =P11 -> 4.8859146e+08 | R11: =Q11 -> 4.8859146e+08 | S11: =R11 -> 4.8859146e+08 | T11: =S11 -> 4.8859146e+08 | U11: =T11 -> 4.8859146e+08 | V11: =U11 -> 4.8859146e+08
A12: C | B12: ='BOBOT PEK'!B29 -> 0 | L12: ='BOBOT PEK'!I40 -> 3908731694 | O12: =L12/2 -> 1954365847 | P12: =O12 -> 1954365847
A13: D | B13: ='BOBOT PEK'!B42 -> 0 | L13: ='BOBOT PEK'!I48 -> 3908731694 | P13: =L13/4 -> 9.7718292e+08 | Q13: =P13 -> 9.7718292e+08 | R13: =Q13 -> 9.7718292e+08 | S13: =R13 -> 9.7718292e+08
A14: E | B14: ='BOBOT PEK'!B50 -> 0 | L14: ='BOBOT PEK'!I57 -> 3908731694 | Q14: =L14/2 -> 1954365847 | R14: =Q14 -> 1954365847
A15: F | B15: ='BOBOT PEK'!B59 -> 0 | L15: ='BOBOT PEK'!I62 -> 3908731694 | R15: =L15/2 -> 1954365847 | S15: =R15 -> 1954365847
A16: G | B16: ='BOBOT PEK'!B64 -> 0 | L16: ='BOBOT PEK'!I70 -> 3908731694 | P16: =L16/2 -> 1954365847 | Q16: =P16 -> 1954365847
A17: H | B17: ='BOBOT PEK'!B72 -> 0 | L17: ='BOBOT PEK'!I80 -> 3908731694 | N17: =L17/13 -> 3.0067167e+08 | O17: =N17 -> 3.0067167e+08 | P17: =O17 -> 3.0067167e+08 | Q17: =P17 -> 3.0067167e+08 | R17: =Q17 -> 3.0067167e+08 | S17: =R17 -> 3.0067167e+08 | T17: =S17 -> 3.0067167e+08 | U17: =T17 -> 3.0067167e+08 | V17: =U17 -> 3.0067167e+08 | W17: =U17 -> 3.0067167e+08 | X17: =W17 -> 3.0067167e+08 | Y17: =X17 -> 3.0067167e+08 | Z17: =Y17 -> 3.0067167e+08
A18: I | B18: ='BOBOT PEK'!B82 -> 0 | L18: ='BOBOT PEK'!I85 -> 3908731694 | R18: =L18/2 -> 1954365847 | S18: =R18 -> 1954365847
A19: J | B19: ='BOBOT PEK'!B87:F87 -> 0 | L19: ='BOBOT PEK'!I104 -> 3908731694 | P19: =L19/8 -> 4.8859146e+08 | Q19: =P19 -> 4.8859146e+08 | R19: =Q19 -> 4.8859146e+08 | S19: =R19 -> 4.8859146e+08 | T19: =S19 -> 4.8859146e+08 | U19: =T19 -> 4.8859146e+08 | V19: =U19 -> 4.8859146e+08 | W19: =U19 -> 4.8859146e+08
A20: K | B20: ='BOBOT PEK'!B107 -> 0 | L20: ='BOBOT PEK'!I113 -> 3908731694 | R20: =L20/6 -> 6.5145528e+08 | S20: =R20 -> 6.5145528e+08 | T20: =S20 -> 6.5145528e+08 | U20: =T20 -> 6.5145528e+08 | V20: =U20 -> 6.5145528e+08 | W20: =V20 -> 6.5145528e+08
A21: L | B21: ='BOBOT PEK'!B115 -> 0 | L21: ='BOBOT PEK'!I119 -> 3908731694 | R21: =L21/2 -> 1954365847 | S21: =R21 -> 1954365847
A22: M | B22: ='BOBOT PEK'!B121 -> 0 | L22: ='BOBOT PEK'!I125 -> 3908731694 | P22: =L22/4 -> 9.7718292e+08 | Q22: =P22 -> 9.7718292e+08 | R22: =Q22 -> 9.7718292e+08 | S22: =R22 -> 9.7718292e+08
A23: N | B23: ='BOBOT PEK'!B127 -> 0 | L23: ='BOBOT PEK'!I131 -> 3908731694 | T23: =L23 -> 3908731694
A24: O | B24: ='BOBOT PEK'!B133 -> 0 | L24: ='BOBOT PEK'!I142 -> 3908731694 | R24: =L24/4 -> 9.7718292e+08 | S24: =R24 -> 9.7718292e+08 | T24: =S24 -> 9.7718292e+08 | U24: =T24 -> 9.7718292e+08
A25: II | B25: ='BOBOT PEK'!B144 -> 0
A26: A | B26: ='BOBOT PEK'!B145 -> 0 | L26: ='BOBOT PEK'!I151 -> 0 | P26: =L26 -> 0
A27: B | B27: ='BOBOT PEK'!B153 -> 0 | L27: ='BOBOT PEK'!I159 -> 0 | Q27: =L27/4 -> 0 | R27: =Q27 -> 0 | S27: =R27 -> 0 | T27: =S27 -> 0
A28: D | B28: ='BOBOT PEK'!B161 -> opsi 1 = Gym Ac Split | L28: ='BOBOT PEK'!I173 -> 0 | S28: =L28/8 -> 0 | T28: =S28 -> 0 | U28: =T28 -> 0 | V28: =U28 -> 0 | W28: =U28 -> 0 | X28: =W28 -> 0 | Y28: =X28 -> 0 | Z28: =Y28 -> 0
A29: III | B29: ='BOBOT PEK'!B175 -> 1
A30: A | B30: ='BOBOT PEK'!B176 -> 2 | L30: ='BOBOT PEK'!I181 -> 0 | P30: =L30 -> 0
A31: B | B31: ='BOBOT PEK'!B182 -> C | L31: ='BOBOT PEK'!I188 -> 0 | Q31: =L31/3 -> 0 | R31: =Q31 -> 0 | S31: =R31 -> 0
A32: C | B32: ='BOBOT PEK'!B189 -> 7 | L32: ='BOBOT PEK'!I192 -> 0 | S32: =L32 -> 0
A33: D | B33: ='BOBOT PEK'!B193 -> 1 | L33: ='BOBOT PEK'!I196 -> 0 | T33: =L33 -> 0
A34: E | B34: ='BOBOT PEK'!B197 -> 5 | L34: ='BOBOT PEK'!I211 -> 0 | U34: =L34/5 -> 0 | V34: =U34 -> 0 | W34: =U34 -> 0 | X34: =W34 -> 0 | Y34: =X34 -> 0
A35: F | B35: ='BOBOT PEK'!B212 -> 1 | L35: ='BOBOT PEK'!I216 -> 3908731694 | Y35: =L35/2 -> 1954365847 | Z35: =Y35 -> 1954365847
A36: G | B36: ='BOBOT PEK'!B217 -> B | L36: ='BOBOT PEK'!I221 -> 3908731694 | W36: =L36/4 -> 9.7718292e+08 | X36: =W36 -> 9.7718292e+08 | Y36: =X36 -> 9.7718292e+08 | Z36: =Y36 -> 9.7718292e+08
B37: TOTAL | L37: =SUM(L9:L36) -> 66448438798
B38: Rencana progress mingguan | M38: =SUM(M9:M36) -> 1954365847 | N38: =SUM(N9:N36) -> 2.2550375e+09 | O38: =SUM(O9:O36) -> 2.743629e+09 | P38: =SUM(P9:P36) -> 7.1409521e+09 | Q38: =SUM(Q9:Q36) -> 7.1409521e+09 | R38: =SUM(R9:R36) -> 1.2678322e+10 | S38: =SUM(S9:S36) -> 1.0723956e+10 | T38: =SUM(T9:T36) -> 6.8152245e+09 | ... Z38: =SUM(Z9:Z36) -> 3.2322204e+09
B39: Rencana komulatif progress mingguan | M39: =M38 -> 1954365847 | N39: =M39+N38 -> 4.2094034e+09 | O39: =N39+O38 -> 6.9530323e+09 | P39: =O39+P38 -> 1.4093984e+10 | Q39: =P39+Q38 -> 2.1234937e+10 | R39: =Q39+R38 -> 3.3913259e+10 | S39: =R39+S38 -> 4.4637215e+10 | T39: =S39+T38 -> 5.1452439e+10 | U39: =T39+U38 -> 5.4358932e+10 | ... Z39: =Y39+Z38 -> 66448438798
B40: Realisasi progress mingguan
B41: Realisasi komulatif progress mingguan

Sheet TS
A6: TIME SCHEDULE
A7: PEKERJAAN : ARTABOGA GATSU
A8: Periode : Juli 2026 s/d November 2026 | F8: Author : | G8: Ryan
A10: NO | B10: URAIAN PEKERJAAN | L10: BOBOT | M10: JULI | N10: AGUSTUS | R10: SEPTEMBER | W10: OKTOBER | AA10: NOVEMBER | AC10: KET
M11: Week 1 | N11: Week 2 | O11: Week 3 | P11: Week 4 | Q11: Week 5 | R11: Week 6 | S11: Week 7 | T11: Week 8 | U11: Week 9 | V11: Week 10 | W11: Week 11 | X11: Week 12 | Y11: Week 13 | Z11: Week 14 | AA11: Week 15 | AB11: Week 16
A12: I | B12: ='BOBOT PEK'!B4:C4 -> Pekerjaan Gudang Umum
A13: A | B13: ='BOBOT PEK'!C8 -> PEKERJAAN PERSIAPAN | I13: plan | L13: ='BOBOT PEK'!J14 -> 1.2791873 | M13: =L13/4 -> 0.31979683 | N13: =M13 -> 0.31979683 | O13: =N13 -> 0.31979683 | P13: =O13 -> 0.31979683
I14: aktual | L14: =SUM(M14:AB14) -> 1.2791873 | M14: =SUM('PRODUKTIVITAS HARIAN'!DV4:DV9) -> 1.010558 | N14: =SUM('PRODUKTIVITAS HARIAN'!DW4:DW9) -> 0 | O14: =SUM('PRODUKTIVITAS HARIAN'!DX4:DX9) -> 0 | P14: =SUM('PRODUKTIVITAS HARIAN'!DY4:DY9) -> 0.076751239 | Q14: =SUM('PRODUKTIVITAS HARIAN'!DZ4:DZ9) -> 0.038375619 | R14: =SUM('PRODUKTIVITAS HARIAN'!EA4:EA9) -> 0.15350248 | S14: =SUM('PRODUKTIVITAS HARIAN'!EB4:EB9) -> 0 | T14: =SUM('PRODUKTIVITAS HARIAN'!EC4:EC9) -> 0 | ... AB14: =SUM('PRODUKTIVITAS HARIAN'!EK4:EK9) -> 0
A15: B | B15: ='BOBOT PEK'!C15 -> PEKERJAAN AREA GUDANG UMUM+GUDANG SPM UK.46X54 M | I15: plan | L15: ='BOBOT PEK'!J29 -> 16.160562 | O15: =L15/7 -> 2.3086517 | P15: =O15 -> 2.3086517 | Q15: =P15 -> 2.3086517 | R15: =Q15 -> 2.3086517 | S15: =R15 -> 2.3086517 | T15: =S15 -> 2.3086517 | U15: =T15 -> 2.3086517
I16: aktual | L16: =SUM(M16:AB16) -> 6.5959631 | M16: =SUM('PRODUKTIVITAS HARIAN'!DV10:DV22) -> 0 | N16: =SUM('PRODUKTIVITAS HARIAN'!DW10:DW22) -> 0 | O16: =SUM('PRODUKTIVITAS HARIAN'!DX10:DX22) -> 0 | P16: =SUM('PRODUKTIVITAS HARIAN'!DY10:DY22) -> 0.00015350248 | Q16: =SUM('PRODUKTIVITAS HARIAN'!DZ10:DZ22) -> 1.7652785 | R16: =SUM('PRODUKTIVITAS HARIAN'!EA10:EA22) -> 0.87496412 | S16: =SUM('PRODUKTIVITAS HARIAN'!EB10:EB22) -> 0.75830224 | T16: =SUM('PRODUKTIVITAS HARIAN'!EC10:EC22) -> 0.48174194 | ... AB16: =SUM('PRODUKTIVITAS HARIAN'!EK10:EK22) -> 0
A17: C | B17: ='BOBOT PEK'!C31 -> PEKERJAAN AREA GUDANG PARKIR SISI SAMPING UK.4,75X37M | I17: plan | L17: ='BOBOT PEK'!J42 -> 1.9395038 | O17: =L17/4 -> 0.48487595 | P17: =O17 -> 0.48487595 | Q17: =P17 -> 0.48487595 | R17: =Q17 -> 0.48487595
I18: aktual | L18: =SUM(M18:AB18) -> 0.029549227 | M18: =SUM('PRODUKTIVITAS HARIAN'!DV23:DV32) -> 0 | N18: =SUM('PRODUKTIVITAS HARIAN'!DW23:DW32) -> 0 | O18: =SUM('PRODUKTIVITAS HARIAN'!DX23:DX32) -> 0 | P18: =SUM('PRODUKTIVITAS HARIAN'!DY23:DY32) -> 0 | Q18: =SUM('PRODUKTIVITAS HARIAN'!DZ23:DZ32) -> 0 | R18: =SUM('PRODUKTIVITAS HARIAN'!EA23:EA32) -> 0 | S18: =SUM('PRODUKTIVITAS HARIAN'!EB23:EB32) -> 0 | T18: =SUM('PRODUKTIVITAS HARIAN'!EC23:EC32) -> 0.0026862934 | ... AB18: =SUM('PRODUKTIVITAS HARIAN'!EK23:EK32) -> 0
A19: D | B19: ='BOBOT PEK'!C44 -> PEKERJAAN PAGAR SAMPING P 40M x T 2,1M | I19: plan | L19: ='BOBOT PEK'!J50 -> 3.3072109 | P19: =L19/4 -> 0.82680272 | Q19: =P19 -> 0.82680272 | R19: =Q19 -> 0.82680272 | S19: =R19 -> 0.82680272
I20: aktual | L20: =SUM(M20:AB20) -> 0.75037128 | M20: =SUM('PRODUKTIVITAS HARIAN'!DV33:DV37) -> 0 | N20: =SUM('PRODUKTIVITAS HARIAN'!DW33:DW37) -> 0 | O20: =SUM('PRODUKTIVITAS HARIAN'!DX33:DX37) -> 0.028142121 | P20: =SUM('PRODUKTIVITAS HARIAN'!DY33:DY37) -> 0 | Q20: =SUM('PRODUKTIVITAS HARIAN'!DZ33:DZ37) -> 0.11589437 | R20: =SUM('PRODUKTIVITAS HARIAN'!EA33:EA37) -> 0 | S20: =SUM('PRODUKTIVITAS HARIAN'!EB33:EB37) -> 0 | T20: =SUM('PRODUKTIVITAS HARIAN'!EC33:EC37) -> 0.30316739 | ... AB20: =SUM('PRODUKTIVITAS HARIAN'!EK33:EK37) -> 0
A21: E | B21: ='BOBOT PEK'!C52 -> PEKERJAAN PAGAR DEPAN PJ,70 M, TINGGI 150 CM | I21: plan | L21: ='BOBOT PEK'!J59 -> 1.2841378 | Y21: =L21/2 -> 0.64206888 | Z21: =Y21 -> 0.64206888
I22: aktual | L22: =SUM(M22:AB22) -> 0.31397397 | M22: =SUM('PRODUKTIVITAS HARIAN'!DV38:DV43) -> 0 | N22: =SUM('PRODUKTIVITAS HARIAN'!DW38:DW43) -> 0 | O22: =SUM('PRODUKTIVITAS HARIAN'!DX38:DX43) -> 0 | P22: =SUM('PRODUKTIVITAS HARIAN'!DY38:DY43) -> 0 | Q22: =SUM('PRODUKTIVITAS HARIAN'!DZ38:DZ43) -> 0 | R22: =SUM('PRODUKTIVITAS HARIAN'!EA38:EA43) -> 0 | S22: =SUM('PRODUKTIVITAS HARIAN'!EB38:EB43) -> 0.041184715 | T22: =SUM('PRODUKTIVITAS HARIAN'!EC38:EC43) -> 0.14366809 | ... AB22: =SUM('PRODUKTIVITAS HARIAN'!EK38:EK43) -> 0
A23: F | B23: ='BOBOT PEK'!C61 -> PEKERJAAN KANOPI GENSET UK. 5.5 X4 M DAN JEMBATAN TIMBANG | I23: plan | L23: ='BOBOT PEK'!J64 -> 0.37032473 | S23: =L23/2 -> 0.18516236 | T23: =S23 -> 0.18516236
I24: aktual | L24: =SUM(M24:AB24) -> 0.05948221 | M24: =SUM('PRODUKTIVITAS HARIAN'!DV44:DV45) -> 0 | N24: =SUM('PRODUKTIVITAS HARIAN'!DW44:DW45) -> 0 | O24: =SUM('PRODUKTIVITAS HARIAN'!DX44:DX45) -> 0 | P24: =SUM('PRODUKTIVITAS HARIAN'!DY44:DY45) -> 0 | Q24: =SUM('PRODUKTIVITAS HARIAN'!DZ44:DZ45) -> 0 | R24: =SUM('PRODUKTIVITAS HARIAN'!EA44:EA45) -> 0 | S24: =SUM('PRODUKTIVITAS HARIAN'!EB44:EB45) -> 0 | T24: =SUM('PRODUKTIVITAS HARIAN'!EC44:EC45) -> 0.01918781 | ... AB24: =SUM('PRODUKTIVITAS HARIAN'!EK44:EK45) -> 0
A25: G | B25: ='BOBOT PEK'!C66 -> PEKERJAAN TAMAN DEPAN UK. 5X8 / 17X8 M, 17X30M, BELAKANG 21X28 / 5X36 M | I25: plan | L25: ='BOBOT PEK'!J72 -> 1.0275712 | P25: =L25/2 -> 0.51378558 | Q25: =P25 -> 0.51378558
I26: aktual | L26: =SUM(M26:AB26) -> 0.73681189 | M26: =SUM('PRODUKTIVITAS HARIAN'!DV46:DV50) -> 0.020466997 | N26: =SUM('PRODUKTIVITAS HARIAN'!DW46:DW50) -> 0.15861923 | O26: =SUM('PRODUKTIVITAS HARIAN'!DX46:DX50) -> 0.16814917 | P26: =SUM('PRODUKTIVITAS HARIAN'!DY46:DY50) -> 0 | Q26: =SUM('PRODUKTIVITAS HARIAN'!DZ46:DZ50) -> 0.051167493 | R26: =SUM('PRODUKTIVITAS HARIAN'!EA46:EA50) -> 0.051167493 | S26: =SUM('PRODUKTIVITAS HARIAN'!EB46:EB50) -> 0 | T26: =SUM('PRODUKTIVITAS HARIAN'!EC46:EC50) -> 0.082571541 | ... AB26: =SUM('PRODUKTIVITAS HARIAN'!EK46:EK50) -> 0
A27: H | B27: ='BOBOT PEK'!C74 -> PEKERJAAN JALAN | I27: plan | L27: ='BOBOT PEK'!J82 -> 42.78671 | M27: =L27/16 -> 2.6741694 | N27: =M27 -> 2.6741694 | O27: =N27 -> 2.6741694 | P27: =O27 -> 2.6741694 | Q27: =P27 -> 2.6741694 | R27: =Q27 -> 2.6741694 | S27: =R27 -> 2.6741694 | T27: =S27 -> 2.6741694 | U27: =T27 -> 2.6741694 | V27: =U27 -> 2.6741694 | W27: =U27 -> 2.6741694 | X27: =W27 -> 2.6741694 | Y27: =X27 -> 2.6741694 | Z27: =Y27 -> 2.6741694 | AA27: =Z27 -> 2.6741694 | AB27: =AA27 -> 2.6741694
I28: aktual | L28: =SUM(M28:AB28) -> 41.967482 | M28: =SUM('PRODUKTIVITAS HARIAN'!DV51:DV55) -> 0.846822 | N28: =SUM('PRODUKTIVITAS HARIAN'!DW51:DW55) -> 5.6667998 | O28: =SUM('PRODUKTIVITAS HARIAN'!DX51:DX55) -> 2.9011968 | P28: =SUM('PRODUKTIVITAS HARIAN'!DY51:DY55) -> 10.553295 | Q28: =SUM('PRODUKTIVITAS HARIAN'!DZ51:DZ55) -> 0.041957344 | R28: =SUM('PRODUKTIVITAS HARIAN'!EA51:EA55) -> 0 | S28: =SUM('PRODUKTIVITAS HARIAN'!EB51:EB55) -> 1.126964 | T28: =SUM('PRODUKTIVITAS HARIAN'!EC51:EC55) -> 9.3330857 | ... AB28: =SUM('PRODUKTIVITAS HARIAN'!EK51:EK55) -> 0
A29: J | B29: ='BOBOT PEK'!C84 -> PEKERJAAN PAGAR PERIMETER P 215M + 91M x T 2,4M | I29: plan | L29: ='BOBOT PEK'!J87 -> 1.8394202 | Y29: =L29/2 -> 0.9197101 | Z29: =Y29 -> 0.9197101
I30: aktual | L30: =SUM(M30:AB30) -> 1.5681557 | M30: =SUM('PRODUKTIVITAS HARIAN'!DV56:DV57) -> 0 | N30: =SUM('PRODUKTIVITAS HARIAN'!DW56:DW57) -> 0 | O30: =SUM('PRODUKTIVITAS HARIAN'!DX56:DX57) -> 0.0058842616 | P30: =SUM('PRODUKTIVITAS HARIAN'!DY56:DY57) -> 0.014710654 | Q30: =SUM('PRODUKTIVITAS HARIAN'!DZ56:DZ57) -> 0.41189832 | R30: =SUM('PRODUKTIVITAS HARIAN'!EA56:EA57) -> 0.40601405 | S30: =SUM('PRODUKTIVITAS HARIAN'!EB56:EB57) -> 0.41925364 | T30: =SUM('PRODUKTIVITAS HARIAN'!EC56:EC57) -> 0.24272579 | ... AB30: =SUM('PRODUKTIVITAS HARIAN'!EK56:EK57) -> 0
A31: K | B31: PEKERJAAN WATER TORN UK 4X4 M, BENGKEL UK. 12X7 M,. dan GUDANG BELAKANG | I31: plan | L31: ='BOBOT PEK'!J106 -> 7.1510281 | P31: =L31/8 -> 0.89387851 | Q31: =P31 -> 0.89387851 | R31: =Q31 -> 0.89387851 | S31: =R31 -> 0.89387851 | T31: =S31 -> 0.89387851 | U31: =T31 -> 0.89387851 | V31: =U31 -> 0.89387851 | W31: =U31 -> 0.89387851
I32: aktual | L32: =SUM(M32:AB32) -> 5.0290891 | M32: =SUM('PRODUKTIVITAS HARIAN'!DV58:DV73) -> 0.36840595 | N32: =SUM('PRODUKTIVITAS HARIAN'!DW58:DW73) -> 0.14736238 | O32: =SUM('PRODUKTIVITAS HARIAN'!DX58:DX73) -> 0 | P32: =SUM('PRODUKTIVITAS HARIAN'!DY58:DY73) -> 0.0061400991 | Q32: =SUM('PRODUKTIVITAS HARIAN'!DZ58:DZ73) -> 1.5913858 | R32: =SUM('PRODUKTIVITAS HARIAN'!EA58:EA73) -> 1.2052656 | S32: =SUM('PRODUKTIVITAS HARIAN'!EB58:EB73) -> 0.98599758 | T32: =SUM('PRODUKTIVITAS HARIAN'!EC58:EC73) -> 0.056540079 | ... AB32: =SUM('PRODUKTIVITAS HARIAN'!EK58:EK73) -> 0
A33: L | B33: ='BOBOT PEK'!C109 -> PEKERJAAN PAVING BLOCK UK. 1,85X169 M DAN SALURAN GOT Timur P 215M | I33: plan | L33: ='BOBOT PEK'!J115 -> 2.1298469 | P33: =L33/6 -> 0.35497448 | Q33: =P33 -> 0.35497448 | R33: =Q33 -> 0.35497448 | S33: =R33 -> 0.35497448 | T33: =S33 -> 0.35497448 | U33: =T33 -> 0.35497448
I34: aktual | L34: =SUM(M34:AB34) -> 1.8804054 | M34: =SUM('PRODUKTIVITAS HARIAN'!DV74:DV78) -> 0.11052178 | N34: =SUM('PRODUKTIVITAS HARIAN'!DW74:DW78) -> 0.18880805 | O34: =SUM('PRODUKTIVITAS HARIAN'!DX74:DX78) -> 0.12894208 | P34: =SUM('PRODUKTIVITAS HARIAN'!DY74:DY78) -> 0.24151057 | Q34: =SUM('PRODUKTIVITAS HARIAN'!DZ74:DZ78) -> 0.3387288 | R34: =SUM('PRODUKTIVITAS HARIAN'!EA74:EA78) -> 0.22718367 | S34: =SUM('PRODUKTIVITAS HARIAN'!EB74:EB78) -> 0.33003033 | T34: =SUM('PRODUKTIVITAS HARIAN'!EC74:EC78) -> 0.17908622 | ... AB34: =SUM('PRODUKTIVITAS HARIAN'!EK74:EK78) -> 0
A35: M | B35: ='BOBOT PEK'!C117 -> PEKERJAAN PENERANGAN JALAN | I35: plan | L35: ='BOBOT PEK'!J121 -> 1.1594554 | Y35: =L35/2 -> 0.57972769 | Z35: =Y35 -> 0.57972769
I36: aktual | L36: =SUM(M36:AB36) -> 1.1401351 | M36: =SUM('PRODUKTIVITAS HARIAN'!DV79:DV81) -> 0 | N36: =SUM('PRODUKTIVITAS HARIAN'!DW79:DW81) -> 0 | O36: =SUM('PRODUKTIVITAS HARIAN'!DX79:DX81) -> 0 | P36: =SUM('PRODUKTIVITAS HARIAN'!DY79:DY81) -> 0 | Q36: =SUM('PRODUKTIVITAS HARIAN'!DZ79:DZ81) -> 0 | R36: =SUM('PRODUKTIVITAS HARIAN'!EA79:EA81) -> 0.5561541 | S36: =SUM('PRODUKTIVITAS HARIAN'!EB79:EB81) -> 0.3632892 | T36: =SUM('PRODUKTIVITAS HARIAN'!EC79:EC81) -> 0.076751239 | ... AB36: =SUM('PRODUKTIVITAS HARIAN'!EK79:EK81) -> 0
A37: N | B37: ='BOBOT PEK'!C123 -> PEKERJAAN SALURAN GOT UTAMA (SEKELILING GUDANG) P156+46+98+17 | I37: plan | L37: ='BOBOT PEK'!J127 -> 1.488974 | W37: =L37/2 -> 0.74448702 | X37: =W37 -> 0.74448702
I38: aktual | L38: =SUM(M38:AB38) -> 0.023025372 | M38: =SUM('PRODUKTIVITAS HARIAN'!DV82:DV84) -> 0 | N38: =SUM('PRODUKTIVITAS HARIAN'!DW82:DW84) -> 0 | O38: =SUM('PRODUKTIVITAS HARIAN'!DX82:DX84) -> 0 | P38: =SUM('PRODUKTIVITAS HARIAN'!DY82:DY84) -> 0 | Q38: =SUM('PRODUKTIVITAS HARIAN'!DZ82:DZ84) -> 0.023025372 | R38: =SUM('PRODUKTIVITAS HARIAN'!EA82:EA84) -> 0 | S38: =SUM('PRODUKTIVITAS HARIAN'!EB82:EB84) -> 0 | T38: =SUM('PRODUKTIVITAS HARIAN'!EC82:EC84) -> 0 | ... AB38: =SUM('PRODUKTIVITAS HARIAN'!EK82:EK84) -> 0
A39: O | B39: ='BOBOT PEK'!C129 -> PEKERJAAN LAIN LAIN | I39: plan | L39: ='BOBOT PEK'!J133 -> 0.47969524 | S39: =L39/2 -> 0.23984762 | T39: =S39 -> 0.23984762
I40: aktual | L40: =SUM(M40:AB40) -> 0.0025583746 | M40: =SUM('PRODUKTIVITAS HARIAN'!DV85:DV87) -> 0 | N40: =SUM('PRODUKTIVITAS HARIAN'!DW85:DW87) -> 0 | O40: =SUM('PRODUKTIVITAS HARIAN'!DX85:DX87) -> 0 | P40: =SUM('PRODUKTIVITAS HARIAN'!DY85:DY87) -> 0 | Q40: =SUM('PRODUKTIVITAS HARIAN'!DZ85:DZ87) -> 0 | R40: =SUM('PRODUKTIVITAS HARIAN'!EA85:EA87) -> 0 | S40: =SUM('PRODUKTIVITAS HARIAN'!EB85:EB87) -> 0 | T40: =SUM('PRODUKTIVITAS HARIAN'!EC85:EC87) -> 0 | ... AB40: =SUM('PRODUKTIVITAS HARIAN'!EK85:EK87) -> 0
A41: P | B41: ='BOBOT PEK'!C135 -> PEKERJAAN INTERIOR | I41: plan | L41: ='BOBOT PEK'!J144 -> 1.5227446 | S41: =L41/4 -> 0.38068614 | T41: =S41 -> 0.38068614 | U41: =T41 -> 0.38068614 | V41: =U41 -> 0.38068614
I42: aktual | L42: =SUM(M42:AB42) -> 0.54861786 | M42: =SUM('PRODUKTIVITAS HARIAN'!DV88:DV95) -> 0 | N42: =SUM('PRODUKTIVITAS HARIAN'!DW88:DW95) -> 0 | O42: =SUM('PRODUKTIVITAS HARIAN'!DX88:DX95) -> 0 | P42: =SUM('PRODUKTIVITAS HARIAN'!DY88:DY95) -> 0 | Q42: =SUM('PRODUKTIVITAS HARIAN'!DZ88:DZ95) -> 0 | R42: =SUM('PRODUKTIVITAS HARIAN'!EA88:EA95) -> 0 | S42: =SUM('PRODUKTIVITAS HARIAN'!EB88:EB95) -> 0.3508555 | T42: =SUM('PRODUKTIVITAS HARIAN'!EC88:EC95) -> 0 | ... AB42: =SUM('PRODUKTIVITAS HARIAN'!EK88:EK95) -> 0
A43: II | B43: ='BOBOT PEK'!B160 -> Pekerjaan Gudang Atas
A44: A | B44: ='BOBOT PEK'!C166 -> PEKERJAAN PERSIAPAN | I44: plan | L44: ='BOBOT PEK'!J172 -> 0.30802831 | U44: =L44 -> 0.30802831
